Workbook

Sheet Resumen
A1: Fixly · Plan de 3 meses: v1 en tiendas + tracción
A2: Del lunes 7 de setiembre al domingo 6 de diciembre de 2026 · 13 semanas · una persona
A4: Objetivo (/goal) | B4: 20 suscripciones pagadas (no trials) a los 60 días de publicar en tiendas.
A5: Producto v1 | B5: Placa → API rellena auto → sube manual PDF → plan por km (extracción por modelo, revisada a mano) → estado → registrar → historial → avisos locales. Trial 14 días, bloqueo total, S/14,90/mes o anual vía IAP. Claro/verde. Solo Perú. Sin web, sin mapa, sin moto, sin login.
A6: Usuario | B6: Joven en Perú con su primer auto (probablemente usado), tiene el manual en PDF, no sabe de mecánica, desconfía del taller.
A7: Supuesto más riesgoso | B7: Que el joven tenga el PDF del manual. Se valida en las semanas 1–2 con 10 entrevistas ANTES de construir la extracción.
A8: Fecha objetivo de publicación | B8: Semana 8 (26 oct – 1 nov). Los 60 días caen el ~25 de diciembre, fuera de este plan: la meta intermedia al 6 de diciembre es 10 pagos.
A9: Restricción 1 · Apple | B9: Enrollment oficial 24–48 h, pero en 2026 hay reportes de 2–7 semanas. Se solicita el DÍA 1 (7 set). Primera revisión de app: 2–5 días.
A10: Restricción 2 · Google Play | B10: Cuenta personal creada después del 13-nov-2023: prueba cerrada con 12 testers opt-in 14 días CONTINUOS y con uso real antes de producción. Debe arrancar en la semana 5 como tarde.
A11: Restricción 3 · Peru Tech Week | B11: 12–18 de octubre (semana 6). Es la única semana del trimestre donde todo el ecosistema está en el mismo lugar: se va con TestFlight en el celular, no con slides.
A12: Restricción 4 · StartUp Perú | B12: Emprendimientos Innovadores (hasta S/67.000) está CERRADO y exige empresa constituida (≤1,5 años) y equipo de 2–4. No aplica en este trimestre; se prepara para la convocatoria 2027.
A13: Sin publicidad pagada | B13: NEGOCIO.md: S/1,04 de valor por instalación vs S/35 de CPI. Todo el crecimiento de este plan es orgánico; el costo es tiempo.
A15: Hojas
A16: Cronograma | B16: Gantt semanal. Las celdas se pintan solas a partir de las columnas Inicio/Fin (fórmula).
A17: Tareas | B17: Todas las tareas con semana, horas, dependencia, entregable y criterio de hecho. Edita 'Estado'.
A18: Contenido | B18: Calendario de publicaciones: LinkedIn, TikTok/Instagram, grupos de Facebook, landing.
A19: Ecosistema | B19: Programas, comunidades, eventos y medios en Perú con qué hacer y cuándo.
A20: Entrevistas | B20: Tres rondas de entrevistas con guion y tracker (el % que tiene el PDF se calcula solo).
A21: Talleres | B21: Plan de reuniones con talleres: para qué, a quién, guion, tracker.
A22: Métricas | B22: Embudo semanal con meta y real; las tasas se calculan con fórmula.
A23: Presupuesto | B23: Todo lo que cuesta dinero en el trimestre, en soles y dólares.
A24: Riesgos | B24: Qué puede fallar, cómo lo detectas a tiempo y qué haces.
A26: Leyenda
A27: Texto azul | B27: Dato de entrada que puedes cambiar (fechas, metas, precios).
A28: Fondo amarillo | B28: Celda para que TÚ llenes cada semana (reales, estado).
A29: Texto negro | B29: Fórmula: no la edites.
A30: Fila de ejemplo | B30: En Entrevistas y Talleres hay una fila marcada EJEMPLO con el formato esperado; bórrala cuando tengas datos reales.
A32: Fuentes
B33: Google Play, requisitos de prueba para cuentas personales: https://support.google.com/googleplay/android-developer/answer/14151465
B34: Google Play 12 testers / 14 días (2026): https://ontest.app/blog/google-play-12-testers-14-days-requirement-explained
B35: App Store review 2026 (2–5 días primera app): https://appcompliance.io/blog/app-store-review-time-2026/
B36: Apple enrollment, demoras 2026: https://www.lance.app/guides/apple-developer-enrollment
B37: Peru Tech Week 12–18 oct 2026: https://techweek.pe/
B38: StartUp Perú · Emprendimientos Innovadores: https://startup.proinnovate.gob.pe/concursos/emprendimientos-innovadores/
B39: Peru Venture Capital Conference: https://www.peruvcconference.com/
B40: NEGOCIO.md, PANTALLAS.md, DETALLE-AUTO.md de este repo (cifras de costo, CPI, precio).

Sheet Cronograma
A1: Cronograma · Gantt semanal
A2: Las barras se pintan por fórmula desde Tareas (semana inicio/fin). Hitos en dorado. No edites las celdas de la grilla.
A4: ID | B4: Frente | C4: Tarea | D4: Ini | E4: Fin | F4: 1 | G4: 2 | H4: 3 | I4: 4 | J4: 5 | K4: 6 | L4: 7 | M4: 8 | N4: 9 | O4: 10 | P4: 11 | Q4: 12 | R4: 13
F5: 46272 | G5: 46279 | H5: 46286 | I5: 46293 | J5: 46300 | K5: 46307 | L5: 46314 | M5: 46321 | N5: 46328 | O5: 46335 | P5: 46342 | Q5: 46349 | R5: 46356
A6: CUENTAS Y TIENDAS
A7: =Tareas!A5 | B7: =Tareas!B5 | C7: =Tareas!C5 | D7: =Tareas!E5 | E7: =Tareas!F5 | F7: =IF(AND(F$4>=$D7,F$4<=$E7),IF(Tareas!$K5="Hecho","✓","■"),"") | G7: =IF(AND(G$4>=$D7,G$4<=$E7),IF(Tareas!$K5="Hecho","✓","■"),"") | H7: =IF(AND(H$4>=$D7,H$4<=$E7),IF(Tareas!$K5="Hecho","✓","■"),"") | I7: =IF(AND(I$4>=$D7,I$4<=$E7),IF(Tareas!$K5="Hecho","✓","■"),"") | J7: =IF(AND(J$4>=$D7,J$4<=$E7),IF(Tareas!$K5="Hecho","✓","■"),"") | K7: =IF(AND(K$4>=$D7,K$4<=$E7),IF(Tareas!$K5="Hecho","✓","■"),"") | L7: =IF(AND(L$4>=$D7,L$4<=$E7),IF(Tareas!$K5="Hecho","✓","■"),"") | M7: =IF(AND(M$4>=$D7,M$4<=$E7),IF(Tareas!$K5="Hecho","✓","■"),"") | ... R7: =IF(AND(R$4>=$D7,R$4<=$E7),IF(Tareas!$K5="Hecho","✓","■"),"")
A8: =Tareas!A6 | B8: =Tareas!B6 | C8: =Tareas!C6 | D8: =Tareas!E6 | E8: =Tareas!F6 | F8: =IF(AND(F$4>=$D8,F$4<=$E8),IF(Tareas!$K6="Hecho","✓","■"),"") | G8: =IF(AND(G$4>=$D8,G$4<=$E8),IF(Tareas!$K6="Hecho","✓","■"),"") | H8: =IF(AND(H$4>=$D8,H$4<=$E8),IF(Tareas!$K6="Hecho","✓","■"),"") | I8: =IF(AND(I$4>=$D8,I$4<=$E8),IF(Tareas!$K6="Hecho","✓","■"),"") | J8: =IF(AND(J$4>=$D8,J$4<=$E8),IF(Tareas!$K6="Hecho","✓","■"),"") | K8: =IF(AND(K$4>=$D8,K$4<=$E8),IF(Tareas!$K6="Hecho","✓","■"),"") | L8: =IF(AND(L$4>=$D8,L$4<=$E8),IF(Tareas!$K6="Hecho","✓","■"),"") | M8: =IF(AND(M$4>=$D8,M$4<=$E8),IF(Tareas!$K6="Hecho","✓","■"),"") | ... R8: =IF(AND(R$4>=$D8,R$4<=$E8),IF(Tareas!$K6="Hecho","✓","■"),"")
A9: =Tareas!A7 | B9: =Tareas!B7 | C9: =Tareas!C7 | D9: =Tareas!E7 | E9: =Tareas!F7 | F9: =IF(AND(F$4>=$D9,F$4<=$E9),IF(Tareas!$K7="Hecho","✓","■"),"") | G9: =IF(AND(G$4>=$D9,G$4<=$E9),IF(Tareas!$K7="Hecho","✓","■"),"") | H9: =IF(AND(H$4>=$D9,H$4<=$E9),IF(Tareas!$K7="Hecho","✓","■"),"") | I9: =IF(AND(I$4>=$D9,I$4<=$E9),IF(Tareas!$K7="Hecho","✓","■"),"") | J9: =IF(AND(J$4>=$D9,J$4<=$E9),IF(Tareas!$K7="Hecho","✓","■"),"") | K9: =IF(AND(K$4>=$D9,K$4<=$E9),IF(Tareas!$K7="Hecho","✓","■"),"") | L9: =IF(AND(L$4>=$D9,L$4<=$E9),IF(Tareas!$K7="Hecho","✓","■"),"") | M9: =IF(AND(M$4>=$D9,M$4<=$E9),IF(Tareas!$K7="Hecho","✓","■"),"") | ... R9: =IF(AND(R$4>=$D9,R$4<=$E9),IF(Tareas!$K7="Hecho","✓","■"),"")
A10: =Tareas!A8 | B10: =Tareas!B8 | C10: =Tareas!C8 | D10: =Tareas!E8 | E10: =Tareas!F8 | F10: =IF(AND(F$4>=$D10,F$4<=$E10),IF(Tareas!$K8="Hecho","✓","■"),"") | G10: =IF(AND(G$4>=$D10,G$4<=$E10),IF(Tareas!$K8="Hecho","✓","■"),"") | H10: =IF(AND(H$4>=$D10,H$4<=$E10),IF(Tareas!$K8="Hecho","✓","■"),"") | I10: =IF(AND(I$4>=$D10,I$4<=$E10),IF(Tareas!$K8="Hecho","✓","■"),"") | J10: =IF(AND(J$4>=$D10,J$4<=$E10),IF(Tareas!$K8="Hecho","✓","■"),"") | K10: =IF(AND(K$4>=$D10,K$4<=$E10),IF(Tareas!$K8="Hecho","✓","■"),"") | L10: =IF(AND(L$4>=$D10,L$4<=$E10),IF(Tareas!$K8="Hecho","✓","■"),"") | M10: =IF(AND(M$4>=$D10,M$4<=$E10),IF(Tareas!$K8="Hecho","✓","■"),"") | ... R10: =IF(AND(R$4>=$D10,R$4<=$E10),IF(Tareas!$K8="Hecho","✓","■"),"")
A11: =Tareas!A9 | B11: =Tareas!B9 | C11: =Tareas!C9 | D11: =Tareas!E9 | E11: =Tareas!F9 | F11: =IF(AND(F$4>=$D11,F$4<=$E11),IF(Tareas!$K9="Hecho","✓","■"),"") | G11: =IF(AND(G$4>=$D11,G$4<=$E11),IF(Tareas!$K9="Hecho","✓","■"),"") | H11: =IF(AND(H$4>=$D11,H$4<=$E11),IF(Tareas!$K9="Hecho","✓","■"),"") | I11: =IF(AND(I$4>=$D11,I$4<=$E11),IF(Tareas!$K9="Hecho","✓","■"),"") | J11: =IF(AND(J$4>=$D11,J$4<=$E11),IF(Tareas!$K9="Hecho","✓","■"),"") | K11: =IF(AND(K$4>=$D11,K$4<=$E11),IF(Tareas!$K9="Hecho","✓","■"),"") | L11: =IF(AND(L$4>=$D11,L$4<=$E11),IF(Tareas!$K9="Hecho","✓","■"),"") | M11: =IF(AND(M$4>=$D11,M$4<=$E11),IF(Tareas!$K9="Hecho","✓","■"),"") | ... R11: =IF(AND(R$4>=$D11,R$4<=$E11),IF(Tareas!$K9="Hecho","✓","■"),"")
A12: =Tareas!A10 | B12: =Tareas!B10 | C12: =Tareas!C10 | D12: =Tareas!E10 | E12: =Tareas!F10 | F12: =IF(AND(F$4>=$D12,F$4<=$E12),IF(Tareas!$K10="Hecho","✓","■"),"") | G12: =IF(AND(G$4>=$D12,G$4<=$E12),IF(Tareas!$K10="Hecho","✓","■"),"") | H12: =IF(AND(H$4>=$D12,H$4<=$E12),IF(Tareas!$K10="Hecho","✓","■"),"") | I12: =IF(AND(I$4>=$D12,I$4<=$E12),IF(Tareas!$K10="Hecho","✓","■"),"") | J12: =IF(AND(J$4>=$D12,J$4<=$E12),IF(Tareas!$K10="Hecho","✓","■"),"") | K12: =IF(AND(K$4>=$D12,K$4<=$E12),IF(Tareas!$K10="Hecho","✓","■"),"") | L12: =IF(AND(L$4>=$D12,L$4<=$E12),IF(Tareas!$K10="Hecho","✓","■"),"") | M12: =IF(AND(M$4>=$D12,M$4<=$E12),IF(Tareas!$K10="Hecho","✓","■"),"") | ... R12: =IF(AND(R$4>=$D12,R$4<=$E12),IF(Tareas!$K10="Hecho","✓","■"),"")
A13: =Tareas!A11 | B13: =Tareas!B11 | C13: =Tareas!C11 | D13: =Tareas!E11 | E13: =Tareas!F11 | F13: =IF(AND(F$4>=$D13,F$4<=$E13),IF(Tareas!$K11="Hecho","✓","■"),"") | G13: =IF(AND(G$4>=$D13,G$4<=$E13),IF(Tareas!$K11="Hecho","✓","■"),"") | H13: =IF(AND(H$4>=$D13,H$4<=$E13),IF(Tareas!$K11="Hecho","✓","■"),"") | I13: =IF(AND(I$4>=$D13,I$4<=$E13),IF(Tareas!$K11="Hecho","✓","■"),"") | J13: =IF(AND(J$4>=$D13,J$4<=$E13),IF(Tareas!$K11="Hecho","✓","■"),"") | K13: =IF(AND(K$4>=$D13,K$4<=$E13),IF(Tareas!$K11="Hecho","✓","■"),"") | L13: =IF(AND(L$4>=$D13,L$4<=$E13),IF(Tareas!$K11="Hecho","✓","■"),"") | M13: =IF(AND(M$4>=$D13,M$4<=$E13),IF(Tareas!$K11="Hecho","✓","■"),"") | ... R13: =IF(AND(R$4>=$D13,R$4<=$E13),IF(Tareas!$K11="Hecho","✓","■"),"")
A14: =Tareas!A12 | B14: =Tareas!B12 | C14: =Tareas!C12 | D14: =Tareas!E12 | E14: =Tareas!F12 | F14: =IF(AND(F$4>=$D14,F$4<=$E14),IF(Tareas!$K12="Hecho","✓","■"),"") | G14: =IF(AND(G$4>=$D14,G$4<=$E14),IF(Tareas!$K12="Hecho","✓","■"),"") | H14: =IF(AND(H$4>=$D14,H$4<=$E14),IF(Tareas!$K12="Hecho","✓","■"),"") | I14: =IF(AND(I$4>=$D14,I$4<=$E14),IF(Tareas!$K12="Hecho","✓","■"),"") | J14: =IF(AND(J$4>=$D14,J$4<=$E14),IF(Tareas!$K12="Hecho","✓","■"),"") | K14: =IF(AND(K$4>=$D14,K$4<=$E14),IF(Tareas!$K12="Hecho","✓","■"),"") | L14: =IF(AND(L$4>=$D14,L$4<=$E14),IF(Tareas!$K12="Hecho","✓","■"),"") | M14: =IF(AND(M$4>=$D14,M$4<=$E14),IF(Tareas!$K12="Hecho","✓","■"),"") | ... R14: =IF(AND(R$4>=$D14,R$4<=$E14),IF(Tareas!$K12="Hecho","✓","■"),"")
A15: =Tareas!A13 | B15: =Tareas!B13 | C15: =Tareas!C13 | D15: =Tareas!E13 | E15: =Tareas!F13 | F15: =IF(AND(F$4>=$D15,F$4<=$E15),IF(Tareas!$K13="Hecho","✓","■"),"") | G15: =IF(AND(G$4>=$D15,G$4<=$E15),IF(Tareas!$K13="Hecho","✓","■"),"") | H15: =IF(AND(H$4>=$D15,H$4<=$E15),IF(Tareas!$K13="Hecho","✓","■"),"") | I15: =IF(AND(I$4>=$D15,I$4<=$E15),IF(Tareas!$K13="Hecho","✓","■"),"") | J15: =IF(AND(J$4>=$D15,J$4<=$E15),IF(Tareas!$K13="Hecho","✓","■"),"") | K15: =IF(AND(K$4>=$D15,K$4<=$E15),IF(Tareas!$K13="Hecho","✓","■"),"") | L15: =IF(AND(L$4>=$D15,L$4<=$E15),IF(Tareas!$K13="Hecho","✓","■"),"") | M15: =IF(AND(M$4>=$D15,M$4<=$E15),IF(Tareas!$K13="Hecho","✓","■"),"") | ... R15: =IF(AND(R$4>=$D15,R$4<=$E15),IF(Tareas!$K13="Hecho","✓","■"),"")
A16: =Tareas!A14 | B16: =Tareas!B14 | C16: =Tareas!C14 | D16: =Tareas!E14 | E16: =Tareas!F14 | F16: =IF(AND(F$4>=$D16,F$4<=$E16),IF(Tareas!$K14="Hecho","✓","■"),"") | G16: =IF(AND(G$4>=$D16,G$4<=$E16),IF(Tareas!$K14="Hecho","✓","■"),"") | H16: =IF(AND(H$4>=$D16,H$4<=$E16),IF(Tareas!$K14="Hecho","✓","■"),"") | I16: =IF(AND(I$4>=$D16,I$4<=$E16),IF(Tareas!$K14="Hecho","✓","■"),"") | J16: =IF(AND(J$4>=$D16,J$4<=$E16),IF(Tareas!$K14="Hecho","✓","■"),"") | K16: =IF(AND(K$4>=$D16,K$4<=$E16),IF(Tareas!$K14="Hecho","✓","■"),"") | L16: =IF(AND(L$4>=$D16,L$4<=$E16),IF(Tareas!$K14="Hecho","✓","■"),"") | M16: =IF(AND(M$4>=$D16,M$4<=$E16),IF(Tareas!$K14="Hecho","✓","■"),"") | ... R16: =IF(AND(R$4>=$D16,R$4<=$E16),IF(Tareas!$K14="Hecho","✓","■"),"")
A17: =Tareas!A15 | B17: =Tareas!B15 | C17: =Tareas!C15 | D17: =Tareas!E15 | E17: =Tareas!F15 | F17: =IF(AND(F$4>=$D17,F$4<=$E17),IF(Tareas!$K15="Hecho","✓","■"),"") | G17: =IF(AND(G$4>=$D17,G$4<=$E17),IF(Tareas!$K15="Hecho","✓","■"),"") | H17: =IF(AND(H$4>=$D17,H$4<=$E17),IF(Tareas!$K15="Hecho","✓","■"),"") | I17: =IF(AND(I$4>=$D17,I$4<=$E17),IF(Tareas!$K15="Hecho","✓","■"),"") | J17: =IF(AND(J$4>=$D17,J$4<=$E17),IF(Tareas!$K15="Hecho","✓","■"),"") | K17: =IF(AND(K$4>=$D17,K$4<=$E17),IF(Tareas!$K15="Hecho","✓","■"),"") | L17: =IF(AND(L$4>=$D17,L$4<=$E17),IF(Tareas!$K15="Hecho","✓","■"),"") | M17: =IF(AND(M$4>=$D17,M$4<=$E17),IF(Tareas!$K15="Hecho","✓","■"),"") | ... R17: =IF(AND(R$4>=$D17,R$4<=$E17),IF(Tareas!$K15="Hecho","✓","■"),"")
A18: =Tareas!A16 | B18: =Tareas!B16 | C18: =Tareas!C16 | D18: =Tareas!E16 | E18: =Tareas!F16 | F18: =IF(AND(F$4>=$D18,F$4<=$E18),IF(Tareas!$K16="Hecho","✓","■"),"") | G18: =IF(AND(G$4>=$D18,G$4<=$E18),IF(Tareas!$K16="Hecho","✓","■"),"") | H18: =IF(AND(H$4>=$D18,H$4<=$E18),IF(Tareas!$K16="Hecho","✓","■"),"") | I18: =IF(AND(I$4>=$D18,I$4<=$E18),IF(Tareas!$K16="Hecho","✓","■"),"") | J18: =IF(AND(J$4>=$D18,J$4<=$E18),IF(Tareas!$K16="Hecho","✓","■"),"") | K18: =IF(AND(K$4>=$D18,K$4<=$E18),IF(Tareas!$K16="Hecho","✓","■"),"") | L18: =IF(AND(L$4>=$D18,L$4<=$E18),IF(Tareas!$K16="Hecho","✓","■"),"") | M18: =IF(AND(M$4>=$D18,M$4<=$E18),IF(Tareas!$K16="Hecho","✓","■"),"") | ... R18: =IF(AND(R$4>=$D18,R$4<=$E18),IF(Tareas!$K16="Hecho","✓","■"),"")
A19: PRODUCTO
A20: =Tareas!A17 | B20: =Tareas!B17 | C20: =Tareas!C17 | D20: =Tareas!E17 | E20: =Tareas!F17 | F20: =IF(AND(F$4>=$D20,F$4<=$E20),IF(Tareas!$K17="Hecho","✓","■"),"") | G20: =IF(AND(G$4>=$D20,G$4<=$E20),IF(Tareas!$K17="Hecho","✓","■"),"") | H20: =IF(AND(H$4>=$D20,H$4<=$E20),IF(Tareas!$K17="Hecho","✓","■"),"") | I20: =IF(AND(I$4>=$D20,I$4<=$E20),IF(Tareas!$K17="Hecho","✓","■"),"") | J20: =IF(AND(J$4>=$D20,J$4<=$E20),IF(Tareas!$K17="Hecho","✓","■"),"") | K20: =IF(AND(K$4>=$D20,K$4<=$E20),IF(Tareas!$K17="Hecho","✓","■"),"") | L20: =IF(AND(L$4>=$D20,L$4<=$E20),IF(Tareas!$K17="Hecho","✓","■"),"") | M20: =IF(AND(M$4>=$D20,M$4<=$E20),IF(Tareas!$K17="Hecho","✓","■"),"") | ... R20: =IF(AND(R$4>=$D20,R$4<=$E20),IF(Tareas!$K17="Hecho","✓","■"),"")
A21: =Tareas!A18 | B21: =Tareas!B18 | C21: =Tareas!C18 | D21: =Tareas!E18 | E21: =Tareas!F18 | F21: =IF(AND(F$4>=$D21,F$4<=$E21),IF(Tareas!$K18="Hecho","✓","■"),"") | G21: =IF(AND(G$4>=$D21,G$4<=$E21),IF(Tareas!$K18="Hecho","✓","■"),"") | H21: =IF(AND(H$4>=$D21,H$4<=$E21),IF(Tareas!$K18="Hecho","✓","■"),"") | I21: =IF(AND(I$4>=$D21,I$4<=$E21),IF(Tareas!$K18="Hecho","✓","■"),"") | J21: =IF(AND(J$4>=$D21,J$4<=$E21),IF(Tareas!$K18="Hecho","✓","■"),"") | K21: =IF(AND(K$4>=$D21,K$4<=$E21),IF(Tareas!$K18="Hecho","✓","■"),"") | L21: =IF(AND(L$4>=$D21,L$4<=$E21),IF(Tareas!$K18="Hecho","✓","■"),"") | M21: =IF(AND(M$4>=$D21,M$4<=$E21),IF(Tareas!$K18="Hecho","✓","■"),"") | ... R21: =IF(AND(R$4>=$D21,R$4<=$E21),IF(Tareas!$K18="Hecho","✓","■"),"")
A22: =Tareas!A19 | B22: =Tareas!B19 | C22: =Tareas!C19 | D22: =Tareas!E19 | E22: =Tareas!F19 | F22: =IF(AND(F$4>=$D22,F$4<=$E22),IF(Tareas!$K19="Hecho","✓","■"),"") | G22: =IF(AND(G$4>=$D22,G$4<=$E22),IF(Tareas!$K19="Hecho","✓","■"),"") | H22: =IF(AND(H$4>=$D22,H$4<=$E22),IF(Tareas!$K19="Hecho","✓","■"),"") | I22: =IF(AND(I$4>=$D22,I$4<=$E22),IF(Tareas!$K19="Hecho","✓","■"),"") | J22: =IF(AND(J$4>=$D22,J$4<=$E22),IF(Tareas!$K19="Hecho","✓","■"),"") | K22: =IF(AND(K$4>=$D22,K$4<=$E22),IF(Tareas!$K19="Hecho","✓","■"),"") | L22: =IF(AND(L$4>=$D22,L$4<=$E22),IF(Tareas!$K19="Hecho","✓","■"),"") | M22: =IF(AND(M$4>=$D22,M$4<=$E22),IF(Tareas!$K19="Hecho","✓","■"),"") | ... R22: =IF(AND(R$4>=$D22,R$4<=$E22),IF(Tareas!$K19="Hecho","✓","■"),"")
A23: =Tareas!A20 | B23: =Tareas!B20 | C23: =Tareas!C20 | D23: =Tareas!E20 | E23: =Tareas!F20 | F23: =IF(AND(F$4>=$D23,F$4<=$E23),IF(Tareas!$K20="Hecho","✓","■"),"") | G23: =IF(AND(G$4>=$D23,G$4<=$E23),IF(Tareas!$K20="Hecho","✓","■"),"") | H23: =IF(AND(H$4>=$D23,H$4<=$E23),IF(Tareas!$K20="Hecho","✓","■"),"") | I23: =IF(AND(I$4>=$D23,I$4<=$E23),IF(Tareas!$K20="Hecho","✓","■"),"") | J23: =IF(AND(J$4>=$D23,J$4<=$E23),IF(Tareas!$K20="Hecho","✓","■"),"") | K23: =IF(AND(K$4>=$D23,K$4<=$E23),IF(Tareas!$K20="Hecho","✓","■"),"") | L23: =IF(AND(L$4>=$D23,L$4<=$E23),IF(Tareas!$K20="Hecho","✓","■"),"") | M23: =IF(AND(M$4>=$D23,M$4<=$E23),IF(Tareas!$K20="Hecho","✓","■"),"") | ... R23: =IF(AND(R$4>=$D23,R$4<=$E23),IF(Tareas!$K20="Hecho","✓","■"),"")
A24: =Tareas!A21 | B24: =Tareas!B21 | C24: =Tareas!C21 | D24: =Tareas!E21 | E24: =Tareas!F21 | F24: =IF(AND(F$4>=$D24,F$4<=$E24),IF(Tareas!$K21="Hecho","✓","■"),"") | G24: =IF(AND(G$4>=$D24,G$4<=$E24),IF(Tareas!$K21="Hecho","✓","■"),"") | H24: =IF(AND(H$4>=$D24,H$4<=$E24),IF(Tareas!$K21="Hecho","✓","■"),"") | I24: =IF(AND(I$4>=$D24,I$4<=$E24),IF(Tareas!$K21="Hecho","✓","■"),"") | J24: =IF(AND(J$4>=$D24,J$4<=$E24),IF(Tareas!$K21="Hecho","✓","■"),"") | K24: =IF(AND(K$4>=$D24,K$4<=$E24),IF(Tareas!$K21="Hecho","✓","■"),"") | L24: =IF(AND(L$4>=$D24,L$4<=$E24),IF(Tareas!$K21="Hecho","✓","■"),"") | M24: =IF(AND(M$4>=$D24,M$4<=$E24),IF(Tareas!$K21="Hecho","✓","■"),"") | ... R24: =IF(AND(R$4>=$D24,R$4<=$E24),IF(Tareas!$K21="Hecho","✓","■"),"")
A25: =Tareas!A22 | B25: =Tareas!B22 | C25: =Tareas!C22 | D25: =Tareas!E22 | E25: =Tareas!F22 | F25: =IF(AND(F$4>=$D25,F$4<=$E25),IF(Tareas!$K22="Hecho","✓","■"),"") | G25: =IF(AND(G$4>=$D25,G$4<=$E25),IF(Tareas!$K22="Hecho","✓","■"),"") | H25: =IF(AND(H$4>=$D25,H$4<=$E25),IF(Tareas!$K22="Hecho","✓","■"),"") | I25: =IF(AND(I$4>=$D25,I$4<=$E25),IF(Tareas!$K22="Hecho","✓","■"),"") | J25: =IF(AND(J$4>=$D25,J$4<=$E25),IF(Tareas!$K22="Hecho","✓","■"),"") | K25: =IF(AND(K$4>=$D25,K$4<=$E25),IF(Tareas!$K22="Hecho","✓","■"),"") | L25: =IF(AND(L$4>=$D25,L$4<=$E25),IF(Tareas!$K22="Hecho","✓","■"),"") | M25: =IF(AND(M$4>=$D25,M$4<=$E25),IF(Tareas!$K22="Hecho","✓","■"),"") | ... R25: =IF(AND(R$4>=$D25,R$4<=$E25),IF(Tareas!$K22="Hecho","✓","■"),"")
A26: =Tareas!A23 | B26: =Tareas!B23 | C26: =Tareas!C23 | D26: =Tareas!E23 | E26: =Tareas!F23 | F26: =IF(AND(F$4>=$D26,F$4<=$E26),IF(Tareas!$K23="Hecho","✓","■"),"") | G26: =IF(AND(G$4>=$D26,G$4<=$E26),IF(Tareas!$K23="Hecho","✓","■"),"") | H26: =IF(AND(H$4>=$D26,H$4<=$E26),IF(Tareas!$K23="Hecho","✓","■"),"") | I26: =IF(AND(I$4>=$D26,I$4<=$E26),IF(Tareas!$K23="Hecho","✓","■"),"") | J26: =IF(AND(J$4>=$D26,J$4<=$E26),IF(Tareas!$K23="Hecho","✓","■"),"") | K26: =IF(AND(K$4>=$D26,K$4<=$E26),IF(Tareas!$K23="Hecho","✓","■"),"") | L26: =IF(AND(L$4>=$D26,L$4<=$E26),IF(Tareas!$K23="Hecho","✓","■"),"") | M26: =IF(AND(M$4>=$D26,M$4<=$E26),IF(Tareas!$K23="Hecho","✓","■"),"") | ... R26: =IF(AND(R$4>=$D26,R$4<=$E26),IF(Tareas!$K23="Hecho","✓","■"),"")
A27: =Tareas!A24 | B27: =Tareas!B24 | C27: =Tareas!C24 | D27: =Tareas!E24 | E27: =Tareas!F24 | F27: =IF(AND(F$4>=$D27,F$4<=$E27),IF(Tareas!$K24="Hecho","✓","■"),"") | G27: =IF(AND(G$4>=$D27,G$4<=$E27),IF(Tareas!$K24="Hecho","✓","■"),"") | H27: =IF(AND(H$4>=$D27,H$4<=$E27),IF(Tareas!$K24="Hecho","✓","■"),"") | I27: =IF(AND(I$4>=$D27,I$4<=$E27),IF(Tareas!$K24="Hecho","✓","■"),"") | J27: =IF(AND(J$4>=$D27,J$4<=$E27),IF(Tareas!$K24="Hecho","✓","■"),"") | K27: =IF(AND(K$4>=$D27,K$4<=$E27),IF(Tareas!$K24="Hecho","✓","■"),"") | L27: =IF(AND(L$4>=$D27,L$4<=$E27),IF(Tareas!$K24="Hecho","✓","■"),"") | M27: =IF(AND(M$4>=$D27,M$4<=$E27),IF(Tareas!$K24="Hecho","✓","■"),"") | ... R27: =IF(AND(R$4>=$D27,R$4<=$E27),IF(Tareas!$K24="Hecho","✓","■"),"")
A28: =Tareas!A25 | B28: =Tareas!B25 | C28: =Tareas!C25 | D28: =Tareas!E25 | E28: =Tareas!F25 | F28: =IF(AND(F$4>=$D28,F$4<=$E28),IF(Tareas!$K25="Hecho","✓","■"),"") | G28: =IF(AND(G$4>=$D28,G$4<=$E28),IF(Tareas!$K25="Hecho","✓","■"),"") | H28: =IF(AND(H$4>=$D28,H$4<=$E28),IF(Tareas!$K25="Hecho","✓","■"),"") | I28: =IF(AND(I$4>=$D28,I$4<=$E28),IF(Tareas!$K25="Hecho","✓","■"),"") | J28: =IF(AND(J$4>=$D28,J$4<=$E28),IF(Tareas!$K25="Hecho","✓","■"),"") | K28: =IF(AND(K$4>=$D28,K$4<=$E28),IF(Tareas!$K25="Hecho","✓","■"),"") | L28: =IF(AND(L$4>=$D28,L$4<=$E28),IF(Tareas!$K25="Hecho","✓","■"),"") | M28: =IF(AND(M$4>=$D28,M$4<=$E28),IF(Tareas!$K25="Hecho","✓","■"),"") | ... R28: =IF(AND(R$4>=$D28,R$4<=$E28),IF(Tareas!$K25="Hecho","✓","■"),"")
A29: =Tareas!A26 | B29: =Tareas!B26 | C29: =Tareas!C26 | D29: =Tareas!E26 | E29: =Tareas!F26 | F29: =IF(AND(F$4>=$D29,F$4<=$E29),IF(Tareas!$K26="Hecho","✓","■"),"") | G29: =IF(AND(G$4>=$D29,G$4<=$E29),IF(Tareas!$K26="Hecho","✓","■"),"") | H29: =IF(AND(H$4>=$D29,H$4<=$E29),IF(Tareas!$K26="Hecho","✓","■"),"") | I29: =IF(AND(I$4>=$D29,I$4<=$E29),IF(Tareas!$K26="Hecho","✓","■"),"") | J29: =IF(AND(J$4>=$D29,J$4<=$E29),IF(Tareas!$K26="Hecho","✓","■"),"") | K29: =IF(AND(K$4>=$D29,K$4<=$E29),IF(Tareas!$K26="Hecho","✓","■"),"") | L29: =IF(AND(L$4>=$D29,L$4<=$E29),IF(Tareas!$K26="Hecho","✓","■"),"") | M29: =IF(AND(M$4>=$D29,M$4<=$E29),IF(Tareas!$K26="Hecho","✓","■"),"") | ... R29: =IF(AND(R$4>=$D29,R$4<=$E29),IF(Tareas!$K26="Hecho","✓","■"),"")
A30: =Tareas!A27 | B30: =Tareas!B27 | C30: =Tareas!C27 | D30: =Tareas!E27 | E30: =Tareas!F27 | F30: =IF(AND(F$4>=$D30,F$4<=$E30),IF(Tareas!$K27="Hecho","✓","■"),"") | G30: =IF(AND(G$4>=$D30,G$4<=$E30),IF(Tareas!$K27="Hecho","✓","■"),"") | H30: =IF(AND(H$4>=$D30,H$4<=$E30),IF(Tareas!$K27="Hecho","✓","■"),"") | I30: =IF(AND(I$4>=$D30,I$4<=$E30),IF(Tareas!$K27="Hecho","✓","■"),"") | J30: =IF(AND(J$4>=$D30,J$4<=$E30),IF(Tareas!$K27="Hecho","✓","■"),"") | K30: =IF(AND(K$4>=$D30,K$4<=$E30),IF(Tareas!$K27="Hecho","✓","■"),"") | L30: =IF(AND(L$4>=$D30,L$4<=$E30),IF(Tareas!$K27="Hecho","✓","■"),"") | M30: =IF(AND(M$4>=$D30,M$4<=$E30),IF(Tareas!$K27="Hecho","✓","■"),"") | ... R30: =IF(AND(R$4>=$D30,R$4<=$E30),IF(Tareas!$K27="Hecho","✓","■"),"")
A31: =Tareas!A28 | B31: =Tareas!B28 | C31: =Tareas!C28 | D31: =Tareas!E28 | E31: =Tareas!F28 | F31: =IF(AND(F$4>=$D31,F$4<=$E31),IF(Tareas!$K28="Hecho","✓","■"),"") | G31: =IF(AND(G$4>=$D31,G$4<=$E31),IF(Tareas!$K28="Hecho","✓","■"),"") | H31: =IF(AND(H$4>=$D31,H$4<=$E31),IF(Tareas!$K28="Hecho","✓","■"),"") | I31: =IF(AND(I$4>=$D31,I$4<=$E31),IF(Tareas!$K28="Hecho","✓","■"),"") | J31: =IF(AND(J$4>=$D31,J$4<=$E31),IF(Tareas!$K28="Hecho","✓","■"),"") | K31: =IF(AND(K$4>=$D31,K$4<=$E31),IF(Tareas!$K28="Hecho","✓","■"),"") | L31: =IF(AND(L$4>=$D31,L$4<=$E31),IF(Tareas!$K28="Hecho","✓","■"),"") | M31: =IF(AND(M$4>=$D31,M$4<=$E31),IF(Tareas!$K28="Hecho","✓","■"),"") | ... R31: =IF(AND(R$4>=$D31,R$4<=$E31),IF(Tareas!$K28="Hecho","✓","■"),"")
A32: =Tareas!A29 | B32: =Tareas!B29 | C32: =Tareas!C29 | D32: =Tareas!E29 | E32: =Tareas!F29 | F32: =IF(AND(F$4>=$D32,F$4<=$E32),IF(Tareas!$K29="Hecho","✓","■"),"") | G32: =IF(AND(G$4>=$D32,G$4<=$E32),IF(Tareas!$K29="Hecho","✓","■"),"") | H32: =IF(AND(H$4>=$D32,H$4<=$E32),IF(Tareas!$K29="Hecho","✓","■"),"") | I32: =IF(AND(I$4>=$D32,I$4<=$E32),IF(Tareas!$K29="Hecho","✓","■"),"") | J32: =IF(AND(J$4>=$D32,J$4<=$E32),IF(Tareas!$K29="Hecho","✓","■"),"") | K32: =IF(AND(K$4>=$D32,K$4<=$E32),IF(Tareas!$K29="Hecho","✓","■"),"") | L32: =IF(AND(L$4>=$D32,L$4<=$E32),IF(Tareas!$K29="Hecho","✓","■"),"") | M32: =IF(AND(M$4>=$D32,M$4<=$E32),IF(Tareas!$K29="Hecho","✓","■"),"") | ... R32: =IF(AND(R$4>=$D32,R$4<=$E32),IF(Tareas!$K29="Hecho","✓","■"),"")
A33: ENTREVISTAS
A34: =Tareas!A30 | B34: =Tareas!B30 | C34: =Tareas!C30 | D34: =Tareas!E30 | E34: =Tareas!F30 | F34: =IF(AND(F$4>=$D34,F$4<=$E34),IF(Tareas!$K30="Hecho","✓","■"),"") | G34: =IF(AND(G$4>=$D34,G$4<=$E34),IF(Tareas!$K30="Hecho","✓","■"),"") | H34: =IF(AND(H$4>=$D34,H$4<=$E34),IF(Tareas!$K30="Hecho","✓","■"),"") | I34: =IF(AND(I$4>=$D34,I$4<=$E34),IF(Tareas!$K30="Hecho","✓","■"),"") | J34: =IF(AND(J$4>=$D34,J$4<=$E34),IF(Tareas!$K30="Hecho","✓","■"),"") | K34: =IF(AND(K$4>=$D34,K$4<=$E34),IF(Tareas!$K30="Hecho","✓","■"),"") | L34: =IF(AND(L$4>=$D34,L$4<=$E34),IF(Tareas!$K30="Hecho","✓","■"),"") | M34: =IF(AND(M$4>=$D34,M$4<=$E34),IF(Tareas!$K30="Hecho","✓","■"),"") | ... R34: =IF(AND(R$4>=$D34,R$4<=$E34),IF(Tareas!$K30="Hecho","✓","■"),"")
A35: =Tareas!A31 | B35: =Tareas!B31 | C35: =Tareas!C31 | D35: =Tareas!E31 | E35: =Tareas!F31 | F35: =IF(AND(F$4>=$D35,F$4<=$E35),IF(Tareas!$K31="Hecho","✓","■"),"") | G35: =IF(AND(G$4>=$D35,G$4<=$E35),IF(Tareas!$K31="Hecho","✓","■"),"") | H35: =IF(AND(H$4>=$D35,H$4<=$E35),IF(Tareas!$K31="Hecho","✓","■"),"") | I35: =IF(AND(I$4>=$D35,I$4<=$E35),IF(Tareas!$K31="Hecho","✓","■"),"") | J35: =IF(AND(J$4>=$D35,J$4<=$E35),IF(Tareas!$K31="Hecho","✓","■"),"") | K35: =IF(AND(K$4>=$D35,K$4<=$E35),IF(Tareas!$K31="Hecho","✓","■"),"") | L35: =IF(AND(L$4>=$D35,L$4<=$E35),IF(Tareas!$K31="Hecho","✓","■"),"") | M35: =IF(AND(M$4>=$D35,M$4<=$E35),IF(Tareas!$K31="Hecho","✓","■"),"") | ... R35: =IF(AND(R$4>=$D35,R$4<=$E35),IF(Tareas!$K31="Hecho","✓","■"),"")
A36: =Tareas!A32 | B36: =Tareas!B32 | C36: =Tareas!C32 | D36: =Tareas!E32 | E36: =Tareas!F32 | F36: =IF(AND(F$4>=$D36,F$4<=$E36),IF(Tareas!$K32="Hecho","✓","■"),"") | G36: =IF(AND(G$4>=$D36,G$4<=$E36),IF(Tareas!$K32="Hecho","✓","■"),"") | H36: =IF(AND(H$4>=$D36,H$4<=$E36),IF(Tareas!$K32="Hecho","✓","■"),"") | I36: =IF(AND(I$4>=$D36,I$4<=$E36),IF(Tareas!$K32="Hecho","✓","■"),"") | J36: =IF(AND(J$4>=$D36,J$4<=$E36),IF(Tareas!$K32="Hecho","✓","■"),"") | K36: =IF(AND(K$4>=$D36,K$4<=$E36),IF(Tareas!$K32="Hecho","✓","■"),"") | L36: =IF(AND(L$4>=$D36,L$4<=$E36),IF(Tareas!$K32="Hecho","✓","■"),"") | M36: =IF(AND(M$4>=$D36,M$4<=$E36),IF(Tareas!$K32="Hecho","✓","■"),"") | ... R36: =IF(AND(R$4>=$D36,R$4<=$E36),IF(Tareas!$K32="Hecho","✓","■"),"")
A37: TALLERES
A38: =Tareas!A33 | B38: =Tareas!B33 | C38: =Tareas!C33 | D38: =Tareas!E33 | E38: =Tareas!F33 | F38: =IF(AND(F$4>=$D38,F$4<=$E38),IF(Tareas!$K33="Hecho","✓","■"),"") | G38: =IF(AND(G$4>=$D38,G$4<=$E38),IF(Tareas!$K33="Hecho","✓","■"),"") | H38: =IF(AND(H$4>=$D38,H$4<=$E38),IF(Tareas!$K33="Hecho","✓","■"),"") | I38: =IF(AND(I$4>=$D38,I$4<=$E38),IF(Tareas!$K33="Hecho","✓","■"),"") | J38: =IF(AND(J$4>=$D38,J$4<=$E38),IF(Tareas!$K33="Hecho","✓","■"),"") | K38: =IF(AND(K$4>=$D38,K$4<=$E38),IF(Tareas!$K33="Hecho","✓","■"),"") | L38: =IF(AND(L$4>=$D38,L$4<=$E38),IF(Tareas!$K33="Hecho","✓","■"),"") | M38: =IF(AND(M$4>=$D38,M$4<=$E38),IF(Tareas!$K33="Hecho","✓","■"),"") | ... R38: =IF(AND(R$4>=$D38,R$4<=$E38),IF(Tareas!$K33="Hecho","✓","■"),"")
A39: =Tareas!A34 | B39: =Tareas!B34 | C39: =Tareas!C34 | D39: =Tareas!E34 | E39: =Tareas!F34 | F39: =IF(AND(F$4>=$D39,F$4<=$E39),IF(Tareas!$K34="Hecho","✓","■"),"") | G39: =IF(AND(G$4>=$D39,G$4<=$E39),IF(Tareas!$K34="Hecho","✓","■"),"") | H39: =IF(AND(H$4>=$D39,H$4<=$E39),IF(Tareas!$K34="Hecho","✓","■"),"") | I39: =IF(AND(I$4>=$D39,I$4<=$E39),IF(Tareas!$K34="Hecho","✓","■"),"") | J39: =IF(AND(J$4>=$D39,J$4<=$E39),IF(Tareas!$K34="Hecho","✓","■"),"") | K39: =IF(AND(K$4>=$D39,K$4<=$E39),IF(Tareas!$K34="Hecho","✓","■"),"") | L39: =IF(AND(L$4>=$D39,L$4<=$E39),IF(Tareas!$K34="Hecho","✓","■"),"") | M39: =IF(AND(M$4>=$D39,M$4<=$E39),IF(Tareas!$K34="Hecho","✓","■"),"") | ... R39: =IF(AND(R$4>=$D39,R$4<=$E39),IF(Tareas!$K34="Hecho","✓","■"),"")
A40: =Tareas!A35 | B40: =Tareas!B35 | C40: =Tareas!C35 | D40: =Tareas!E35 | E40: =Tareas!F35 | F40: =IF(AND(F$4>=$D40,F$4<=$E40),IF(Tareas!$K35="Hecho","✓","■"),"") | G40: =IF(AND(G$4>=$D40,G$4<=$E40),IF(Tareas!$K35="Hecho","✓","■"),"") | H40: =IF(AND(H$4>=$D40,H$4<=$E40),IF(Tareas!$K35="Hecho","✓","■"),"") | I40: =IF(AND(I$4>=$D40,I$4<=$E40),IF(Tareas!$K35="Hecho","✓","■"),"") | J40: =IF(AND(J$4>=$D40,J$4<=$E40),IF(Tareas!$K35="Hecho","✓","■"),"") | K40: =IF(AND(K$4>=$D40,K$4<=$E40),IF(Tareas!$K35="Hecho","✓","■"),"") | L40: =IF(AND(L$4>=$D40,L$4<=$E40),IF(Tareas!$K35="Hecho","✓","■"),"") | M40: =IF(AND(M$4>=$D40,M$4<=$E40),IF(Tareas!$K35="Hecho","✓","■"),"") | ... R40: =IF(AND(R$4>=$D40,R$4<=$E40),IF(Tareas!$K35="Hecho","✓","■"),"")
A41: =Tareas!A36 | B41: =Tareas!B36 | C41: =Tareas!C36 | D41: =Tareas!E36 | E41: =Tareas!F36 | F41: =IF(AND(F$4>=$D41,F$4<=$E41),IF(Tareas!$K36="Hecho","✓","■"),"") | G41: =IF(AND(G$4>=$D41,G$4<=$E41),IF(Tareas!$K36="Hecho","✓","■"),"") | H41: =IF(AND(H$4>=$D41,H$4<=$E41),IF(Tareas!$K36="Hecho","✓","■"),"") | I41: =IF(AND(I$4>=$D41,I$4<=$E41),IF(Tareas!$K36="Hecho","✓","■"),"") | J41: =IF(AND(J$4>=$D41,J$4<=$E41),IF(Tareas!$K36="Hecho","✓","■"),"") | K41: =IF(AND(K$4>=$D41,K$4<=$E41),IF(Tareas!$K36="Hecho","✓","■"),"") | L41: =IF(AND(L$4>=$D41,L$4<=$E41),IF(Tareas!$K36="Hecho","✓","■"),"") | M41: =IF(AND(M$4>=$D41,M$4<=$E41),IF(Tareas!$K36="Hecho","✓","■"),"") | ... R41: =IF(AND(R$4>=$D41,R$4<=$E41),IF(Tareas!$K36="Hecho","✓","■"),"")
...

Sheet Tareas
A1: Tareas detalladas
A2: Semanas 1–13 (7 set – 6 dic 2026). Edita solo la columna Estado (amarilla). Horas son estimación para una persona.
A4: ID | B4: Frente | C4: Tarea | D4: Cómo / detalle | E4: Semana inicio | F4: Semana fin | G4: Horas est. | H4: Depende de | I4: Entregable | J4: Criterio de hecho | K4: Estado
A5: A01 | B5: Cuentas y tiendas | C5: Solicitar Apple Developer Program (individual, US$99) | D5: Nombre legal exacto como en DNI. Si pide ID, responder el mismo día. Es la cola más larga del plan. | E5: 1 | F5: 1 | G5: 1 | I5: Cuenta activa | J5: Estado 'Active' en developer.apple.com | K5: Pendiente
A6: A02 | B6: Cuentas y tiendas | C6: Crear cuenta Google Play Console (US$25) | D6: Verificar identidad. Anotar si la cuenta es personal (aplica regla 12 testers/14 días) o de organización (no aplica). | E6: 1 | F6: 1 | G6: 1 | I6: Cuenta verificada | J6: Acceso a Play Console | K6: Pendiente
A7: A03 | B7: Cuentas y tiendas | C7: Cuenta EAS (Expo) + proyecto vinculado | D7: eas init, eas build:configure. Plan gratuito alcanza para el trimestre. | E7: 1 | F7: 1 | G7: 2 | I7: eas.json en repo | J7: Primer build de desarrollo iOS/Android corre | K7: Pendiente
A8: A04 | B8: Cuentas y tiendas | C8: RevenueCat (o expo-iap) configurado | D8: Productos: fixly_mensual (S/14,90) y fixly_anual. Trial 14 días como oferta introductoria en ambas tiendas. | E8: 3 | F8: 3 | G8: 4 | H8: A01,A02 | I8: Productos creados en App Store Connect y Play Console | J8: Compra sandbox funciona en ambos | K8: Pendiente
A9: A05 | B9: Cuentas y tiendas | C9: Política de privacidad + términos (página estática) | D9: Ley 29733 (datos personales, Perú). Qué guardas: placa, km, manual. Publicar en tu VPS. Ambas tiendas la exigen. | E9: 2 | F9: 2 | G9: 3 | I9: URL pública | J9: URL cargada en App Store Connect y Play Console | K9: Pendiente
A10: A06 | B10: Cuentas y tiendas | C10: Ficha de tienda: nombre, subtítulo, descripción, capturas, ícono | D10: 6 capturas por plataforma con el flujo real (placa → manual → plan). Texto para el joven, no para el mecánico. | E10: 7 | F10: 7 | G10: 8 | H10: P05,P04 | I10: Assets subidos | J10: Ficha completa en ambas consolas | K10: Pendiente
A11: A07 | B11: Cuentas y tiendas | C11: TestFlight interno (hasta 100 testers, sin revisión) | D11: Build de producción iOS al grupo interno. Enlace público de TestFlight para las entrevistas de la ronda 2. | E11: 4 | F11: 4 | G11: 2 | H11: A01,P04 | I11: Enlace TestFlight | J11: ≥5 personas instalaron | K11: Pendiente
A12: A08 | B12: Cuentas y tiendas | C12: Prueba cerrada Google Play: reclutar 12+ testers reales | D12: Reclutar 15 (margen). Amigos con Android que de verdad abran la app. Lista de correos en Play Console. El reloj de 14 días arranca cuando hay 12 opt-in. | E12: 4 | F12: 5 | G12: 4 | H12: A02,P04 | I12: Track cerrado con 15 opt-in | J12: 12 opt-in continuos confirmados en consola | K12: Pendiente
A13: A09 | B13: Cuentas y tiendas | C13: Prueba cerrada Google Play: 14 días continuos con uso | D13: No tocar el track. Recordar a los testers que abran la app 2 veces por semana (Google verifica uso en 2026). | E13: 5 | F13: 7 | G13: 2 | H13: A08 | I13: 14 días completados | J13: Botón 'Solicitar acceso a producción' habilitado | K13: Pendiente
A14: A10 | B14: Cuentas y tiendas | C14: Enviar a revisión App Store | D14: Primera app: 2–5 días. Adjuntar cuenta demo no aplica (no hay login). Explicar en notas que la placa se consulta a API pública. Enviar el LUNES de la semana 8. | E14: 8 | F14: 8 | G14: 2 | H14: A04,A05,A06,P12 | I14: App 'Waiting for Review' | J14: Estado 'Ready for Sale' | K14: Pendiente
A15: A11 | B15: Cuentas y tiendas | C15: Solicitar producción Google Play | D15: Formulario de acceso a producción. Responde en 1–7 días. | E15: 8 | F15: 8 | G15: 1 | H15: A09 | I15: Solicitud enviada | J15: Estado 'Producción' publicado | K15: Pendiente
A16: A12 | B16: Cuentas y tiendas | C16: PUBLICACIÓN en ambas tiendas | D16: Hito. Día 0 de los 60. | E16: 8 | F16: 8 | G16: 0 | H16: A10,A11 | I16: App en App Store y Play Store | J16: Enlaces públicos funcionando | K16: Pendiente
A17: P01 | B17: Producto | C17: Podar el repo: quitar mapa, documentos, proforma, reportes, chatbot, cuenta; ocultar moto | D17: Rutas fuera del Stack y del home. Código de moto se queda sin picker. Commit en inglés. | E17: 1 | F17: 1 | G17: 6 | I17: Rama v1 limpia | J17: 14 rutas → 10; app compila | K17: Pendiente
A18: P02 | B18: Producto | C18: Backend mínimo: /placa (json.pe) + /manual (subida) | D18: Un servicio (Vercel/Railway). Alerta de consumo de créditos json.pe. Guardar PDF en storage. | E18: 1 | F18: 2 | G18: 16 | I18: Backend desplegado | J18: Placa real devuelve marca/modelo/año; PDF sube | K18: Pendiente
A19: P03 | B19: Producto | C19: Extracción del manual v0 (LLM) + checklist de revisión manual | D19: Prompt de detalle-auto/manual-extraction-prompt.md. Salida: intervalos por componente con página de origen. Tú revisas cada modelo ANTES de publicarlo. | E19: 2 | F19: 3 | G19: 20 | H19: P02,E01 | I19: Pipeline + tabla de specs por modelo | J19: 3 manuales extraídos y revisados con página citada | K19: Pendiente
A20: P04 | B20: Producto | C20: Trial 14 días + paywall (bloqueo total) + IAP | D20: Estado de suscripción desde RevenueCat. Pantalla de bloqueo con el plan del usuario visible detrás, desenfocado. | E20: 3 | F20: 4 | G20: 14 | H20: A04 | I20: Paywall funcional | J20: Trial → bloqueo → compra sandbox → desbloqueo | K20: Pendiente
A21: P05 | B21: Producto | C21: Kilometraje: campo al abrir (>7 días) + estimado por promedio | D21: Cada lectura es un registro nuevo. Etiqueta 'estimado' visible. | E21: 2 | F21: 2 | G21: 6 | I21: KmPrompt conectado | J21: Estimado aparece tras 8 días sin lectura | K21: Pendiente
A22: P06 | B22: Producto | C22: Notificaciones locales: km cada 14 días + servicio próximo | D22: expo-notifications local. Permiso pedido en el momento útil, no en onboarding. | E22: 4 | F22: 4 | G22: 6 | H22: P05 | I22: Avisos programados | J22: Aviso llega a los 14 días en dev build | K22: Pendiente
A23: P07 | B23: Producto | C23: Auto usado: 'asumir que todo se hizo al comprarlo' | D23: Botón en el primer uso: fija fecha y km de compra como última vez de cada servicio. | E23: 2 | F23: 2 | G23: 4 | I23: Flujo de primer uso | J23: Plan calcula desde km de compra | K23: Pendiente
A24: P08 | B24: Producto | C24: Precargar 10 modelos (por si el usuario no tiene PDF) | D24: Decidido por E01. Manuales públicos de fabricante: Yaris, Rio, Accent, CS35 Plus, Tiggo 2, Spark, Onix, Swift, Sentra, Versa (ajustar según entrevistas). | E24: 4 | F24: 5 | G24: 20 | H24: E01,P03 | I24: 10 specs revisadas | J24: Cada spec con fuente y página | K24: Pendiente
A25: P09 | B25: Producto | C25: Estados: carga, vacío, error de placa, sin conexión | D25: PANTALLAS.md sección 'Estados que hay que pedir'. Sin spinners. | E25: 3 | F25: 3 | G25: 6 | I25: Estados en 4 pantallas | J25: QA manual en simulador | K25: Pendiente
A26: P10 | B26: Producto | C26: Exportar plan como imagen compartible (con marca Fixly) | D26: Único mecanismo de referido sin backend. react-native-view-shot + share. | E26: 7 | F26: 7 | G26: 6 | I26: Botón 'Compartir plan' | J26: Imagen sale por WhatsApp | K26: Pendiente
A27: P11 | B27: Producto | C27: Analítica de producto (PostHog): embudo placa→manual→plan→km→trial→pago | D27: Eventos con nombres fijos. Sin PII. Es lo que alimenta la hoja Métricas. | E27: 5 | F27: 5 | G27: 5 | I27: Dashboard de embudo | J27: 7 eventos visibles en PostHog | K27: Pendiente
A28: P12 | B28: Producto | C28: QA en dispositivos reales (iOS + 2 Android baratos) | D28: Samsung/Xiaomi de gama baja: es lo que tiene el usuario. Teclado, permisos, notificaciones. | E28: 7 | F28: 8 | G28: 10 | H28: P04,P06 | I28: Lista de bugs cerrada | J28: 0 bugs bloqueantes | K28: Pendiente
A29: P13 | B29: Producto | C29: Correcciones post-lanzamiento (semanal) | D29: Reservar 1 día/semana. Sin funciones nuevas hasta la semana 13. | E29: 9 | F29: 13 | G29: 25 | H29: A12 | I29: Releases semanales | J29: Crash-free ≥ 99% | K29: Pendiente
A30: E01 | B30: Entrevistas | C30: Ronda 1: 10 entrevistas de problema (¿tiene el PDF?) | D30: Jóvenes con primer auto, 20–30 min por videollamada o café. Guion en hoja Entrevistas. Decide P08. | E30: 1 | F30: 2 | G30: 12 | I30: 10 fichas llenas | J30: Sabes el % que tiene el PDF y de dónde | K30: Pendiente
A31: E02 | B31: Entrevistas | C31: Ronda 2: 8 pruebas de uso con TestFlight/APK | D31: Los ves subir SU manual y leer SU plan. Grabar pantalla con permiso. Anotar dónde se traban. | E31: 5 | F31: 6 | G31: 10 | H31: A07,E01 | I31: 8 grabaciones + lista de fricciones | J31: Top 5 fricciones priorizadas en P12 | K31: Pendiente
A32: E03 | B32: Entrevistas | C32: Ronda 3: 8 entrevistas de pago y churn | D32: A usuarios reales del día 12–20 de trial: pagaron, no pagaron, desinstalaron. Por qué. Es la única forma de saber si S/14,90 y el bloqueo total aguantan. | E32: 11 | F32: 12 | G32: 10 | H32: A12 | I32: Síntesis de 1 página | J32: Decisión sobre precio/paywall para v1.1 | K32: Pendiente
A33: T01 | B33: Talleres | C33: Lista de 20 talleres y mecánicos de barrio (Lima) | D33: Cerca de donde viven tus entrevistados. Nombre, dueño, WhatsApp, marcas que atienden. | E33: 3 | F33: 3 | G33: 3 | I33: Hoja Talleres llena | J33: 20 filas | K33: Pendiente
A34: T02 | B34: Talleres | C34: Reuniones con talleres: 2 por semana | D34: Objetivo: validar intervalos y precios habituales de los 10 modelos, y que el taller acepte el plan como 'orden' del cliente. Guion en hoja Talleres. | E34: 4 | F34: 12 | G34: 36 | H34: T01 | I34: 18 reuniones | J34: ≥10 talleres validaron precios de ≥1 servicio | K34: Pendiente
A35: T03 | B35: Talleres | C35: Tabla de precios habituales por servicio (Lima) | D35: Sale de T02. Alimenta el rango de precio en servicio/[id]. Marcar fuente y fecha. | E35: 6 | F35: 8 | G35: 6 | H35: T02 | I35: Tabla en src/data | J35: Rango de precio en 10 servicios | K35: Pendiente
A36: T04 | B36: Talleres | C36: 3 talleres 'amigos' que recomiendan Fixly al joven | D36: Sticker/QR en mostrador + plan impreso. Es canal de adquisición en el momento del dolor. | E36: 9 | F36: 11 | G36: 6 | H36: T02 | I36: 3 acuerdos verbales | J36: QR escaneado ≥ 10 veces | K36: Pendiente
A37: C01 | B37: Contenido | C37: Landing en tu VPS: fixly + una página por modelo precargado | D37: Estático. 'Mantenimiento <modelo>: qué toca a cada km'. Botón a tiendas. SEO barato que crece con cada manual. | E37: 5 | F37: 7 | G37: 12 | H37: P08 | I37: 11 páginas publicadas | J37: Indexadas en Google (Search Console) | K37: Pendiente
A38: C02 | B38: Contenido | C38: LinkedIn: 2 publicaciones por semana, construir en público | D38: Calendario en hoja Contenido. Aprendizajes, números reales, no anuncios. | E38: 1 | F38: 13 | G38: 26 | I38: 26 publicaciones | J38: Ver hoja Contenido | K38: Pendiente
A39: C03 | B39: Contenido | C39: TikTok + Instagram Reels: 3 videos por semana desde la semana 3 | D39: Formato: 'Qué le toca a tu <modelo> a los X km'. 30–45 s, cámara al celular. Un modelo por video. | E39: 3 | F39: 13 | G39: 44 | H39: P03 | I39: 33 videos | J39: ≥1 video con >5.000 vistas | K39: Pendiente
A40: C04 | B40: Contenido | C40: Grupos de Facebook de dueños por modelo (Perú) | D40: Unirse a 10 grupos en la semana 2. Participar respondiendo dudas reales. Compartir captura del plan (no link) desde la semana 7. | E40: 2 | F40: 13 | G40: 13 | I40: Presencia en 10 grupos | J40: ≥20 instalaciones atribuidas | K40: Pendiente
A41: C05 | B41: Contenido | C41: Marketplace / vendedores de usados: 10 contactos | D41: Vendedores de Yaris/Rio/Accent en Facebook Marketplace. Ofrecer el plan del auto para el comprador. | E41: 9 | F41: 12 | G41: 8 | H41: P10 | I41: 10 contactos, 3 activos | J41: ≥5 instalaciones atribuidas | K41: Pendiente
...

Sheet Contenido
A1: Calendario de contenido
A2: Construir en público. Cada pieza responde una pregunta que el joven ya se hace; el CTA es siempre 'escribe tu placa'. Edita Estado.
A4: Semana | B4: Fecha | C4: Canal | D4: Tema / gancho | E4: Formato | F4: CTA | G4: Métrica | H4: Estado
A5: 1 | B5: 46273 | C5: LinkedIn | D5: Por qué cerré 4 pantallas que ya estaban construidas (mapa, chatbot, proforma, reportes) | E5: Texto + captura del antes/después | F5: Escribe tu placa (link a tienda desde S8) | G5: Impresiones / comentarios | H5: Pendiente
A6: 1 | B6: 46275 | C6: LinkedIn | D6: El activo que nadie puede comprar: manuales de Changan, Chery y Jetour en Perú | E6: Texto largo | F6: Escribe tu placa (link a tienda desde S8) | G6: Impresiones / comentarios | H6: Pendiente
A7: 2 | B7: 46280 | C7: LinkedIn | D7: 10 entrevistas: ¿cuántos jóvenes tienen el manual de su primer auto en PDF? (número real) | E7: Texto + gráfico simple | F7: Escribe tu placa (link a tienda desde S8) | G7: Impresiones / comentarios | H7: Pendiente
A8: 2 | B8: 46282 | C8: LinkedIn | D8: Cuánto cuesta consultar una placa por API: S/0,011. Por qué el costo no es el problema | E8: Texto | F8: Escribe tu placa (link a tienda desde S8) | G8: Impresiones / comentarios | H8: Pendiente
A9: 3 | B9: 46287 | C9: LinkedIn | D9: Extraer intervalos de un manual de 300 páginas con un LLM: dónde se equivoca | E9: Texto + captura de error real | F9: Escribe tu placa (link a tienda desde S8) | G9: Impresiones / comentarios | H9: Pendiente
A10: 3 | B10: 46289 | C10: LinkedIn | D10: Por qué reviso cada manual a mano antes de publicarlo | E10: Texto corto | F10: Escribe tu placa (link a tienda desde S8) | G10: Impresiones / comentarios | H10: Pendiente
A11: 4 | B11: 46294 | C11: LinkedIn | D11: Primer TestFlight: qué se rompió en un Android de S/400 | E11: Texto + foto | F11: Escribe tu placa (link a tienda desde S8) | G11: Impresiones / comentarios | H11: Pendiente
A12: 4 | B12: 46296 | C12: LinkedIn | D12: Trial de 14 días y bloqueo total: la apuesta que más miedo me da | E12: Texto | F12: Escribe tu placa (link a tienda desde S8) | G12: Impresiones / comentarios | H12: Pendiente
A13: 5 | B13: 46301 | C13: LinkedIn | D13: La regla de Google Play que nadie te cuenta: 12 testers, 14 días, uso real | E13: Texto (guía) | F13: Escribe tu placa (link a tienda desde S8) | G13: Impresiones / comentarios | H13: Pendiente
A14: 5 | B14: 46303 | C14: LinkedIn | D14: Precargué 10 modelos: cuáles y por qué esos | E14: Carrusel | F14: Escribe tu placa (link a tienda desde S8) | G14: Impresiones / comentarios | H14: Pendiente
A15: 6 | B15: 46308 | C15: LinkedIn | D15: Peru Tech Week: voy sin slides, con la app en el celular | E15: Texto corto + foto | F15: Escribe tu placa (link a tienda desde S8) | G15: Impresiones / comentarios | H15: Pendiente
A16: 6 | B16: 46310 | C16: LinkedIn | D16: Lo que 15 desconocidos me dijeron de Fixly en 3 días | E16: Texto | F16: Escribe tu placa (link a tienda desde S8) | G16: Impresiones / comentarios | H16: Pendiente
... A68: 11 | B68: 46342 | C68: Grupos de Facebook | D68: Pedir a usuarios que pagaron que compartan su plan en su grupo | E68: Imagen del plan | F68: Ninguno hasta S7; luego captura, no link | G68: Instalaciones atribuidas | H68: Pendiente
C70: Piezas totales | D70: =COUNTA(D5:D68)
C71: LinkedIn | D71: =COUNTIF(C5:C68,"LinkedIn")
C72: TikTok + IG | D72: =COUNTIF(C5:C68,"TikTok + IG Reels")
C73: Publicadas | D73: =COUNTIF(H5:H68,"Publicado")

Sheet Ecosistema
A1: Ecosistema: programas, comunidades, eventos y medios (Perú)
A2: Verificado el 6 set 2026 donde se indica fuente. Lo que no tiene fecha, confírmalo tú antes de la semana indicada.
A4: Tipo | B4: Nombre | C4: Qué es / requisito | D4: Qué hacer | E4: Semana | F4: URL / contacto | G4: Estado
A5: Evento | B5: Peru Tech Week 2026 | C5: 12–18 de octubre, Lima. Semana nacional de tecnología: fundadores, inversores, corporativos. Ancla Peru VC Conference y Experiencia Endeavor. Verificado. | D5: Inscribirse en S3 a 3 eventos abiertos. Ir con TestFlight. Meta: 15 conversaciones, 5 testers, 3 contactos de talleres/concesionarios. | E5: 3 | F5: https://techweek.pe/ | G5: Pendiente
A6: Evento | B6: Peru Venture Capital Conference (11.ª ed.) | C6: Dentro de Tech Week. Orientado a capital. No vas a levantar plata: vas a escuchar qué preguntan los fondos peruanos a apps de consumo. | D6: Asistir solo si hay entrada accesible; si no, ir a los side events gratuitos. | E6: 6 | F6: https://www.peruvcconference.com/ | G6: Pendiente
A7: Evento | B7: AWS Startup Connect Lima | C7: Evento recurrente de AWS para startups en Lima. Créditos de nube posibles (AWS Activate). | D7: Asistir a la siguiente edición. Pedir AWS Activate (créditos para el backend). | E7: 4 | F7: https://aws.amazon.com/startups/events/aws-startup-connect-lima?lang=es | G7: Pendiente
A8: Comunidad | B8: Startup Grind Lima | C8: Meetups mensuales con fundadores. Open networking. | D8: 1 asistencia al mes. Presentar 2 minutos si hay espacio. | E8: 4 | F8: Buscar 'Startup Grind Lima' en Meetup/Eventbrite | G8: Pendiente
A9: Comunidad | B9: Emprende UP · Startup Fest | C9: Incubadora de la U. del Pacífico; organiza Startup Fest. | D9: Asistir al Startup Fest si cae en el trimestre; pedir reunión en S12 con métricas. | E9: 12 | F9: https://emprendeup.pe/ | G9: Pendiente
A10: Incubadora | B10: UTEC Ventures | C10: Aceleradora de UTEC, programa intensivo de 3 meses, foco tecnológico. +54 startups. | D10: Reunión en S12–13 con 4 semanas de datos en tienda. Sin datos no vale la pena. | E10: 12 | F10: https://utec.edu.pe/ (UTEC Ventures) | G10: Pendiente
A11: Incubadora | B11: Wayra Perú (Telefónica) | C11: Aceleradora corporativa. Abre convocatorias por temas digitales. | D11: Solo si abren convocatoria de movilidad/consumo en el trimestre. Revisar en S8. | E11: 8 | F11: https://www.telefonica.com/ (Wayra) | G11: Pendiente
A12: Fondo público | B12: StartUp Perú · Emprendimientos Innovadores (ProInnóvate) | C12: Hasta S/67.000 no reembolsables. CERRADO. Exige empresa ≤1,5 años constituida, ventas ≤S/120k, equipo 2–4 personas, 1 dedicado 100%. Verificado. | D12: No aplica en 2026. En S12 decidir si constituir empresa y buscar cofundador para la convocatoria 2027. Escribir a startup@proinnovate.gob.pe para fechas. | E12: 12 | F12: https://startup.proinnovate.gob.pe/concursos/emprendimientos-innovadores/ | G12: Pendiente
A13: Fondo público | B13: StartUp Perú · Emprendimientos Dinámicos | C13: Hasta S/150.000. Exige 1–5 años y ventas ≥S/120.000. No aplica. | D13: Ignorar hasta tener ventas. | E13: 0 | F13: https://startup.proinnovate.gob.pe/concursos/emprendimientosdinamicos/ | G13: No aplica
A14: Red | B14: Endeavor Perú | C14: Red de emprendedores de alto impacto. Experiencia Endeavor dentro de Tech Week. | D14: Solo el evento abierto de Tech Week. | E14: 6 | F14: https://endeavor.org.pe/ | G14: Pendiente
A15: Red | B15: PECAP (Asoc. Peruana de Capital Semilla y Emprendedor) | C15: Organiza Tech Week. Lista de fondos y ángeles peruanos. | D15: Seguir en LinkedIn; no pedir reuniones hasta tener número. | E15: 6 | F15: https://pecap.pe/ | G15: Pendiente
A16: Medio | B16: Gestión · sección Emprende | C16: Diario económico peruano. Cubre startups peruanas con historia. | D16: Pitch en S8–9: 'manuales de marcas chinas que ningún proveedor tiene'. | E16: 8 | F16: gestion.pe | G16: Pendiente
... A22: Talleres/Concesionarios | B22: Concesionarios de Changan, Chery, JAC (Lima) | C22: Venden a compradores de primer auto. Su manual es el que nadie tiene. | D22: Contactar a 3 en Tech Week o por LinkedIn en S9: entregar el plan al comprador con el auto. | E22: 9 | F22: LinkedIn / visita | G22: Pendiente

Sheet Entrevistas
A1: Entrevistas de usuario
A2: Ronda 1 (S1–2): problema. Ronda 2 (S5–6): uso con TestFlight/APK. Ronda 3 (S11–12): pago y churn. Llena el tracker; los porcentajes se calculan solos.
A4: Guion · Ronda 1 (20–30 min, no vendas nada, no muestres la app)
A5: 1. Cuéntame de tu auto: qué es, año, cuántos km, cuándo lo compraste, nuevo o usado.
A6: 2. ¿Tienes el manual del propietario? ¿En papel, PDF, ninguno? Si PDF: ¿de dónde lo sacaste? (LA pregunta)
A7: 3. La última vez que le hiciste algo al auto: ¿qué fue, quién decidió que tocaba, cuánto pagaste?
A8: 4. ¿Cómo sabes cuándo le toca algo? (esperar a que suene / el mecánico / calendario / no sé)
A9: 5. ¿Alguna vez sentiste que te cobraron de más? ¿Qué hiciste?
A10: 6. ¿Sabes cuántos km tiene hoy tu auto sin mirar? (mide si el km está en la cabeza)
A11: 7. ¿Qué apps usas para el auto hoy? ¿Pagas por alguna?
A12: 8. Si algo te dijera exactamente qué toca y cuánto debería costar, ¿cuánto pagarías al mes? (anclar: nada / S/5 / S/15 / S/30)
A13: 9. ¿Me pasas el PDF del manual ahora por WhatsApp? (si lo tiene, lo hace; si no lo hace, no lo tiene)
... A19: Tracker
A20: # | B20: Ronda | C20: Fecha | D20: Nombre / alias | E20: Auto (modelo, año, km) | F20: ¿Tiene PDF? (Sí/No) | G20: Fuente del PDF | H20: Pagaría S/ al mes | I20: Cita textual clave | J20: Fricción / hallazgo | K20: Aceptó ronda 2
A21: 1 | B21: 1 | C21: 46274 | D21: EJEMPLO · Diego | E21: Kia Rio 2016, 92.000 km, usado | F21: Sí | G21: Página de Kia Perú | H21: 15 | I21: 'No sé si el cambio de aceite era a los 5 o 10 mil' | J21: No sabe su km sin mirar | K21: Sí
A22: 2
A23: 3
A24: 4
A25: 5
A26: 6
A27: 7
A28: 8
A29: 9
A30: 10
A31: 11
A32: 12
A33: 13
... A47: 27
A49: Resumen
A50: Entrevistas hechas | D50: =COUNTA(D21:D47)
A51: Tienen el PDF | D51: =COUNTIF(F21:F47,"Sí")
A52: % que tiene el PDF | D52: =IF(COUNTA(F21:F47)=0,0,COUNTIF(F21:F47,"Sí")/COUNTA(F21:F47))
A53: Pagarían ≥ S/15 (n) | D53: =COUNTIF(H21:H47,">=15")
A54: Promedio que pagarían (S/) | D54: =IFERROR(AVERAGE(H21:H47),0)
A55: Decisión P08 (precarga) | D55: =IF(COUNTA(F21:F47)<8,"Faltan entrevistas",IF(COUNTIF(F21:F47,"Sí")/COUNTA(F21:F47)<0.5,"PRECARGAR modelos: la puerta principal es elegir modelo","Subir PDF puede ser la puerta principal"))
A56: Regla: si menos del 50% tiene el PDF, la precarga por modelo (P08) pasa de 'por si acaso' a puerta principal de v1.

Sheet Talleres
A1: Reuniones con talleres
A2: Para qué: validar intervalos y precios habituales de los 10 modelos, y convertir 3 talleres en canal (QR en mostrador). 2 reuniones por semana, S4–S12.
A4: Qué NO es esto: no vendes nada al taller, no cobras comisión, no prometes clientes. Vas a aprender y a que te conozcan.
A5: Guion (30 min, en el taller, en hora muerta — martes/miércoles 10–11 am)
A6: 1. Presentación de 1 frase: 'Estoy haciendo una app que convierte el manual del auto en un plan de mantenimiento, para jóvenes con su primer auto. Quiero validar con quien sabe.'
A7: 2. ¿Qué modelos ves más en jóvenes / primer auto? (confirma la lista de 10)
A8: 3. Para <modelo>: ¿cada cuánto haces cambio de aceite, filtros, frenos, faja/cadena, refrigerante, bujías? ¿Cuánto cobras por cada uno con repuesto y sin repuesto? (tabla T03)
A9: 4. ¿En qué se diferencia lo que dice el manual de lo que tú recomiendas en Lima? ¿Por qué? (polvo, tráfico, combustible)
A10: 5. Muéstrale el plan de ese modelo en la app. ¿Qué está mal? ¿Qué falta?
A11: 6. ¿Qué pasa cuando un cliente llega con una lista de lo que quiere que le hagan? ¿Te sirve o te estorba?
A12: 7. Cierre: '¿Te molestaría que le diga a mis usuarios que aquí hacen esto bien?' Si dice que sí: sticker/QR en S9 (T04).
A13: 8. Pedir referido: 'qué otro taller respetas por aquí'.
A15: Tracker
A16: # | B16: Semana | C16: Fecha | D16: Taller | E16: Distrito | F16: Contacto / WhatsApp | G16: Marcas que atiende | H16: Precios validados (n servicios) | I16: Acepta QR (Sí/No) | J16: Notas
A17: 1 | B17: 4 | C17: 46294 | D17: EJEMPLO · Taller Don Pepe | E17: San Juan de Lurigancho | F17: 999 999 999 | G17: Toyota, Kia, Hyundai | H17: 4 | I17: Sí | J17: Aceite cada 5.000 en Lima, no 10.000. Faja Accent: S/450–600.
A18: 2
A19: 3
A20: 4
A21: 5
A22: 6
A23: 7
A24: 8
A25: 9
A26: 10
A27: 11
A28: 12
A29: 13
... A37: 21
A39: Reuniones hechas | E39: =COUNTA(D17:D37)
A40: Servicios con precio validado | E40: =SUM(H17:H37)
A41: Talleres que aceptan QR | E41: =COUNTIF(I17:I37,"Sí")
A42: Meta T02 (≥10 talleres con ≥1 precio) | E42: =COUNTIF(H17:H37,">=1")&" / 10"

Sheet Métricas
A1: Métricas semanales
A2: Una pregunta por semana. Metas en azul (cámbialas si quieres); reales en amarillo (llénalos el viernes). Tasas por fórmula.
A4: Semana | B4: Inicio | C4: Pregunta de la semana | D4: Métrica que manda | E4: Meta | F4: Real | G4: Instal. | H4: Placas | I4: Manuales | J4: Plan visto | K4: Km a 14d | L4: Trials | M4: Pagos | N4: Placa/Inst. | O4: Manual/Placa | P4: Pago/Trial
A5: 1 | B5: 46272 | C5: ¿Tienen el PDF? | D5: Entrevistas ronda 1 | E5: 5 | N5: =IF(G5>0,H5/G5,"") | O5: =IF(H5>0,I5/H5,"") | P5: =IF(L5>0,M5/L5,"")
A6: 2 | B6: 46279 | C6: ¿Tienen el PDF? (cierre) | D6: Entrevistas ronda 1 acumuladas | E6: 10 | N6: =IF(G6>0,H6/G6,"") | O6: =IF(H6>0,I6/H6,"") | P6: =IF(L6>0,M6/L6,"")
A7: 3 | B7: 46286 | C7: ¿La extracción cita página correcta? | D7: Manuales extraídos y revisados | E7: 3 | N7: =IF(G7>0,H7/G7,"") | O7: =IF(H7>0,I7/H7,"") | P7: =IF(L7>0,M7/L7,"")
A8: 4 | B8: 46293 | C8: ¿Instalan el TestFlight? | D8: Testers iOS + Android opt-in | E8: 15 | N8: =IF(G8>0,H8/G8,"") | O8: =IF(H8>0,I8/H8,"") | P8: =IF(L8>0,M8/L8,"")
A9: 5 | B9: 46300 | C9: ¿Completan placa→plan solos? | D9: Pruebas de uso completadas | E9: 4 | N9: =IF(G9>0,H9/G9,"") | O9: =IF(H9>0,I9/H9,"") | P9: =IF(L9>0,M9/L9,"")
A10: 6 | B10: 46307 | C10: ¿Tech Week trae testers? | D10: Contactos nuevos con app instalada | E10: 5 | N10: =IF(G10>0,H10/G10,"") | O10: =IF(H10>0,I10/H10,"") | P10: =IF(L10>0,M10/L10,"")
A11: 7 | B11: 46314 | C11: ¿Está listo para enviar? | D11: Bugs bloqueantes abiertos | E11: 0 | N11: =IF(G11>0,H11/G11,"") | O11: =IF(H11>0,I11/H11,"") | P11: =IF(L11>0,M11/L11,"")
A12: 8 | B12: 46321 | C12: ¿Publicó? | D12: App en ambas tiendas (1=sí) | E12: 1 | G12: 40 | H12: 25 | I12: 12 | J12: 10 | K12: 0 | L12: 0 | M12: 0 | N12: =IF(G12>0,H12/G12,"") | O12: =IF(H12>0,I12/H12,"") | P12: =IF(L12>0,M12/L12,"")
A13: 9 | B13: 46328 | C13: ¿Alguien desconocido escribe su placa? | D13: Placas de no-conocidos | E13: 20 | G13: 120 | H13: 70 | I13: 35 | J13: 30 | K13: 5 | L13: 10 | M13: 0 | N13: =IF(G13>0,H13/G13,"") | O13: =IF(H13>0,I13/H13,"") | P13: =IF(L13>0,M13/L13,"")
A14: 10 | B14: 46335 | C14: ¿Suben el manual? | D14: Manuales subidos por desconocidos | E14: 10 | G14: 220 | H14: 130 | I14: 65 | J14: 55 | K14: 15 | L14: 25 | M14: 2 | N14: =IF(G14>0,H14/G14,"") | O14: =IF(H14>0,I14/H14,"") | P14: =IF(L14>0,M14/L14,"")
A15: 11 | B15: 46342 | C15: ¿Actualizan km a los 14 días? | D15: Usuarios con 2.ª lectura de km | E15: 8 | G15: 320 | H15: 190 | I15: 95 | J15: 80 | K15: 25 | L15: 40 | M15: 5 | N15: =IF(G15>0,H15/G15,"") | O15: =IF(H15>0,I15/H15,"") | P15: =IF(L15>0,M15/L15,"")
A16: 12 | B16: 46349 | C16: ¿Pagan al día 15? | D16: Suscripciones pagadas acumuladas | E16: 5 | G16: 420 | H16: 250 | I16: 125 | J16: 105 | K16: 35 | L16: 55 | M16: 8 | N16: =IF(G16>0,H16/G16,"") | O16: =IF(H16>0,I16/H16,"") | P16: =IF(L16>0,M16/L16,"")
A17: 13 | B17: 46356 | C17: ¿Seguir, corregir o parar? | D17: Suscripciones pagadas acumuladas | E17: 10 | G17: 520 | H17: 310 | I17: 155 | J17: 130 | K17: 45 | L17: 70 | M17: 10 | N17: =IF(G17>0,H17/G17,"") | O17: =IF(H17>0,I17/H17,"") | P17: =IF(L17>0,M17/L17,"")
C18: Las columnas G–M desde la semana 8 son METAS ACUMULADAS desde la publicación (azul). Escribe el real al lado en tu copia o sobreescribe en azul y anota la fecha. Meta final: 20 pagos al día 60 (~25 dic), 10 al 6 dic.
C20: Supuestos del embudo (edítalos):
C21: Placa / instalación | E21: 0.6 | F21: Sin login, la placa es la primera pantalla
C22: Manual / placa | E22: 0.5 | F22: Depende de E01. Si <50% tiene PDF, la precarga sube esto
C23: Km actualizado a 14 días / plan visto | E23: 0.35 | F23: La señal del hábito. Si baja de 25% el bloqueo del día 15 falla
C24: Trial iniciado / plan visto | E24: 0.55 | F24: Trial automático al ver el plan
C25: Pago / trial | E25: 0.15 | F25: NEGOCIO.md usa 12% de inicio de trial; 15% pago/trial es optimista para B2C LatAm
C26: Instalaciones necesarias para 20 pagos | E26: =ROUNDUP(20/(E21*E22*E24*E25),0)
C27: Lectura: con estos supuestos, 20 pagos exigen ~esa cantidad de instalaciones orgánicas en 60 días. Si el número te parece imposible sin publicidad, el problema es el embudo, no el contenido.

Sheet Presupuesto
A1: Presupuesto del trimestre
A2: Lo único que cuesta dinero. Todo lo demás es tiempo. Tipo de cambio editable.
A4: Tipo de cambio S/ por US$ | B4: 3.75 | C4: Supuesto: referencia set 2026, ajústalo.
A6: Concepto | B6: Moneda | C6: Monto | D6: Veces | E6: Total moneda | F6: Total S/ | G6: Semana | H6: Nota / fuente
A7: Apple Developer Program (anual) | B7: USD | C7: 99 | D7: 1 | E7: =C7*D7 | F7: =IF(B7="USD",E7*$B$4,E7) | G7: 1 | H7: Obligatorio para publicar iOS. developer.apple.com/programs/enroll
A8: Google Play Console (único) | B8: USD | C8: 25 | D8: 1 | E8: =C8*D8 | F8: =IF(B8="USD",E8*$B$4,E8) | G8: 1 | H8: Pago único. play.google.com/console
A9: EAS Build (plan gratuito) | B9: USD | C9: 0 | D9: 3 | E9: =C9*D9 | F9: =IF(B9="USD",E9*$B$4,E9) | G9: 1 | H9: Free tier: builds limitados/mes. Si se acaban, plan Starter ~US$19/mes.
A10: Backend (Vercel/Railway, hobby) | B10: USD | C10: 5 | D10: 3 | E10: =C10*D10 | F10: =IF(B10="USD",E10*$B$4,E10) | G10: 1 | H10: Puede ser US$0 en free tier; se presupuesta US$5/mes por si acaso.
A11: json.pe plan Básico (consultas de placa) | B11: PEN | C11: 30 | D11: 3 | E11: =C11*D11 | F11: =IF(B11="USD",E11*$B$4,E11) | G11: 2 | H11: NEGOCIO.md: 500 consultas/mes ≈ S/4 de datos; el plan mínimo cuesta más que el uso. Verificar precio actual en json.pe.
A12: LLM para extracción de manuales | B12: USD | C12: 0.8 | D12: 30 | E12: =C12*D12 | F12: =IF(B12="USD",E12*$B$4,E12) | G12: 2 | H12: Supuesto: ~US$0,80 por manual de 300 páginas (entrada ~250k tokens). 30 manuales en el trimestre. Verificar con tu proveedor.
A13: Dominio (fixly.pe o similar) | B13: USD | C13: 40 | D13: 1 | E13: =C13*D13 | F13: =IF(B13="USD",E13*$B$4,E13) | G13: 5 | H13: Anual. Punto.pe o registrador equivalente.
A14: 2 Android de gama baja usados para QA | B14: PEN | C14: 350 | D14: 2 | E14: =C14*D14 | F14: =IF(B14="USD",E14*$B$4,E14) | G14: 6 | H14: Samsung/Xiaomi de segunda: es el teléfono del usuario.
A15: Stickers/QR para talleres (impresión) | B15: PEN | C15: 60 | D15: 1 | E15: =C15*D15 | F15: =IF(B15="USD",E15*$B$4,E15) | G15: 9 | H15: 20 unidades.
A16: Entradas Peru Tech Week / meetups | B16: PEN | C16: 150 | D16: 1 | E16: =C16*D16 | F16: =IF(B16="USD",E16*$B$4,E16) | G16: 6 | H16: Muchos side events son gratis; reserva por si hay uno pagado.
A17: Cafés / pasajes para entrevistas y talleres | B17: PEN | C17: 15 | D17: 50 | E17: =C17*D17 | F17: =IF(B17="USD",E17*$B$4,E17) | G17: 1 | H17: 26 entrevistas + 18 talleres + margen.
A18: Imprevistos (10%) | B18: PEN | C18: =SUM(F7:F17)*0.1 | D18: 1 | E18: =C18*D18 | F18: =IF(B18="USD",E18*$B$4,E18) | G18: 1 | H18: Fórmula sobre el subtotal.
E20: TOTAL S/ | F20: =SUM(F7:F18)
E21: TOTAL US$ | F21: =F20/$B$4
A23: Ingreso neto por suscripción
A24: Precio mensual S/ | C24: 14.9
A25: Comisión tienda (Small Business Program) | C25: 0.15
A26: Neto por suscriptor / mes S/ | C26: =C24*(1-C25)
A27: Suscriptores para cubrir el presupuesto del trimestre en 3 meses | C27: =ROUNDUP(F20/(C26*3),0)
A28: Nota: Apple y Google cobran el 15% en el programa de pequeños negocios (<US$1M/año). Perú aplica IGV 18% sobre el precio en tienda; verifica si el precio S/14,90 es con o sin impuesto en App Store Connect.

Sheet Riesgos
A1: Riesgos y señales de alerta
